Workbook

Sheet @總表
A1: 動能資產配置 | C1: py自動更新版 | R1: 動能投資原理 | Z1: 原版雙動能
A2: 類型 | B2: timing | C2: 更新日期 | D2: 代號 | E2: 期間報酬 | F2: 代號 | G2: 期間報酬 | H2: 代號 | I2: 期間報酬 | J2: 代號 | K2: 期間報酬 | L2: 最終標的 | R2: 1.資產進攻使用相對動能，盡可能買進最強勢資產 | Z2: 包含資產 | AA2: SPY | AB2: EFA | AC2: AGG
A3: 原版雙動能 | R3: 2.資產防守使用絕對動能，確保有最低上漲 | Z3: 比較標準 | AA3: BIL | AB3: 每月底VS | AC3: SPY/EFA
A4: 股/債 | B4: 本期 | C4: =VOO!A2 | D4: VOO | E4: =V12 | F4: VXUS | G4: =V13 | H4: BND | I4: =V14 | J4: BIL | K4: =V11 | L4: =IF(E4<K4,H4,IF(E4>=G4,D4,F4)) | Z4: 12月漲幅 | AA4: SPY>BIL | AB4: SPY VS EFA
A5: 原版雙動能(拉風增強版)
A6: 股/債 | B6: 本期 | C6: =VOO!A2 | D6: QQQ | E6: =V30 | F6: VXUS | G6: =V13 | H6: BND | I6: =V14 | J6: BIL | K6: =V11 | L6: =IF(AND(E6>G6,E6>0),D6,IF(AND(G6>E6,G6>0),F6,IF(I6>0,H6,J6)))
A7: 加速雙動能(防禦要考慮TLT) | E7: 動能分數 | G7: 動能分數 | I7: 動能分數 | K7: 動能分數 | W7: VAA | X7: 雙動能 | AA7: SPY<BIL | AB7: AGG
A8: 股/債 | B8: 本期 | C8: =VOO!A2 | D8: VOO | E8: =X16 | F8: SCZ | G8: =X17 | H8: TLT | I8: =S18 | J8: BIL | K8: =S19 | L8: =IF(AND(G8>E8,G8>0),F8,IF(AND(E8>G8,E8>0),D8,IF(I8>0,H8,J8))) | R8: 代號 | S8: 1月漲幅 | T8: 3月漲幅 | U8: 6月漲幅 | V8: 12月漲幅 | W8: 動能分數 | X8: 加速動能
A9: 騷速雙動能(加入最拉風的QQQ)
A10: 股/債 | B10: 本期 | C10: =VOO!A2 | D10: QQQ | E10: =X30 | F10: SCZ | G10: =X17 | H10: TLT | I10: =S18 | J10: BIL | K10: =S19 | L10: =IF(AND(E10>G10,E10>0),D10,IF(AND(G10>E10,G10>0),F10,IF(I10>0,H10,J10)))
A11: VAA(攻擊型) | R11: BIL | S11: =BIL!B3/BIL!C3-1 | T11: =BIL!B3/BIL!C5-1 | U11: =BIL!B3/BIL!C8-1 | V11: =BIL!C2/BIL!B13-1 | W11: =(S11*12+T11*4+U11*2+V11*1) | X11: =(S11+T11+U11)/3 | Z11: 加速雙動能
A12: 攻擊資產 | B12: 本期 | C12: =VOO!A2 | D12: SPY | E12: =W21 | F12: EFA | G12: =W22 | H12: EEM | I12: =W23 | J12: AGG | K12: =W24 | L12: =IF(OR(E12<0, G12<0, I12<0, K12<0), A13, IF(E12=MAX(E12, G12, I12, K12), D12, IF(G12=MAX(E12, G12, I12, K12), F12, IF(I12=MAX(E12, G12, I12, K12), H12, IF(K12=MAX(E12, G12, I12, K12), J12) ) ) ) ) | R12: VOO | S12: =VOO!B3/VOO!C3-1 | T12: =VOO!B3/VOO!C5-1 | U12: =VOO!B3/VOO!C8-1 | V12: =VOO!C2/VOO!B13-1 | W12: =(S12*12+T12*4+U12*2+V12*1) | X12: =(S12+T12+U12)/3 | Z12: 包含資產 | AA12: VOO | AB12: SCZ | AC12: TLT
A13: 防禦資產 | B13: 本期 | C13: =VOO!A2 | D13: LQD | E13: =W25 | F13: IEF | G13: =W26 | H13: SHY | I13: =W27 | J13: BIL | K13: =W28 | L13: =IF(L12=A13,IF(E13=MAX(E13,G13,I13,K13),D13,IF(G13=MAX(E13,G13,I13,K13),F13,IF(I13=MAX(E13,G13,I13,K13),H13,IF(K13=MAX(E13,G13,I13,K13),J13)))),A12) | R13: VXUS | S13: =VXUS!B3/VXUS!C3-1 | T13: =VXUS!B3/VXUS!C5-1 | U13: =VXUS!B3/VXUS!C8-1 | V13: =VXUS!C2/VXUS!B13-1 | W13: =(S13*12+T13*4+U13*2+V13*1) | X13: =(S13+T13+U13)/3 | Z13: 比較標準 | AA13: 1.3.6平均 | AB13: VOO>SCZ>0→VOO
R14: BND | S14: 0.01 | T14: =BND!B3/BND!C5-1 | U14: =BND!B3/BND!C8-1 | V14: =BND!C2/BND!B13-1 | W14: =(S14*12+T14*4+U14*2+V14*1) | X14: =(S14+T14+U14)/3 | AB14: SCZ>VOO>0→SCZ
AB15: 只要都<0 →TLT
R16: VOO | S16: =S12 | T16: =T12 | U16: =U12 | V16: =V12 | W16: =(S16*12+T16*4+U16*2+V16*1) | X16: =(S16+T16+U16)/3 | Z16: 加速防禦 | AA16: 多考慮TLT(近1月)<0→現金
A17: 小記錄 | R17: SCZ(VSS) | S17: =VSS!B3/VSS!C3-1 | T17: =VSS!B3/VSS!C5-1 | U17: =VSS!B3/VSS!C8-1 | V17: =VSS!C2/VSS!B13-1 | W17: =(S17*12+T17*4+U17*2+V17*1) | X17: =(S17+T17+U17)/3
A18: 45323 | B18: 在VAA攻擊型出現防禦資產，VAA防禦型給出LQD | R18: TLT | S18: =TLT!B3/TLT!C3-1 | T18: =TLT!B3/TLT!C5-1 | U18: =TLT!B3/TLT!C8-1 | V18: =TLT!C2/TLT!B13-1 | W18: =(S18*12+T18*4+U18*2+V18*1) | X18: =(S18+T18+U18)/3 | Z18: VAA(攻擊型)
B19: 但在雙動能依舊是VOO為主 | E19: 資金流出不夠全面，新興市場偏弱這樣 | R19: BLI | S19: =S11 | T19: =T11 | U19: =U11 | V19: =V11 | W19: =(S19*12+T19*4+U19*2+V19*1) | X19: =(S19+T19+U19)/3 | Z19: 比較資產 | AA19: 攻擊型資產 | AB19: 防禦型資產
B20: 多做了一個騷速雙動能，為了把QQQ擺上，之後就可以直接比較QQQ,VOO | W20: =(S20*12+T20*4+U20*2+V20*1) | X20: =(S20+T20+U20)/3 | Z20: 比較標準 | AA20: 1.3.6.12平均
R21: SPY(VOO) | S21: =S12 | T21: =T12 | U21: =U12 | V21: =V12 | W21: =(S21*12+T21*4+U21*2+V21*1) | X21: =(S21+T21+U21)/3 | AA21: ALL(攻擊型)>0→ALL IN最強
R22: EFA(VXUS) | S22: =S13 | T22: =T13 | U22: =U13 | V22: =V13 | W22: =(S22*12+T22*4+U22*2+V22*1) | X22: =(S22+T22+U22)/3 | AA22: IF NOT → ALL IN 最強防禦資產
A23: 45352 | B23: 全力看多中，怎麼看都是狂飆狀態，但是vaa攻擊型依然以防禦資產為主，有可能頭部到了 | R23: EEM(VWO) | S23: =VWO!B3/VWO!C3-1 | T23: =VWO!B3/VWO!C5-1 | U23: =VWO!B3/VWO!C8-1 | V23: =VWO!C2/VWO!B13-1 | W23: =(S23*12+T23*4+U23*2+V23*1) | X23: =(S23+T23+U23)/3
A24: 45384 | B24: 手工爬蟲越來越順暢了… 不可以這麼慵懶，應該想辦法把它自動化 | R24: AGG(BND) | S24: =S14 | T24: =T14 | U24: =U14 | V24: =V14 | W24: =(S24*12+T24*4+U24*2+V24*1) | X24: =(S24+T24+U24)/3 | Z24: 報酬回測網站
B25: 這波太猛烈，連vaa都顯示攻擊資產，確實標普500這波日K就像昨天看到那樣一路蛇上去 | R25: LQD | S25: =LQD!B3/LQD!C3-1 | T25: =LQD!B3/LQD!C5-1 | U25: =LQD!B3/LQD!C8-1 | V25: =LQD!C2/LQD!B13-1 | W25: =(S25*12+T25*4+U25*2+V25*1) | X25: =(S25+T25+U25)/3 | Z25: Portfolio Visualizer
B26: 眼睛閉著乖乖做多 | R26: IEF | S26: =IEF!B3/IEF!C3-1 | T26: =IEF!B3/IEF!C5-1 | U26: =IEF!B3/IEF!C8-1 | V26: =IEF!C2/IEF!B13-1 | W26: =(S26*12+T26*4+U26*2+V26*1) | X26: =(S26+T26+U26)/3 | Z26: Allocate Smartly
B27: 其實最詭異的是右方所有的標的，近一個月報酬全是正的 | R27: SHY | S27: =SHY!B3/SHY!C3-1 | T27: =SHY!B3/SHY!C5-1 | U27: =SHY!B3/SHY!C8-1 | V27: =SHY!C2/SHY!B13-1 | W27: =(S27*12+T27*4+U27*2+V27*1) | X27: =(S27+T27+U27)/3 | Z27: Porfoliocharts
A28: 45414 | B28: 總算看到修正，但以雙動能來說依然做多，而vaa明顯已經轉為防禦資產 | R28: BIL | S28: =S11 | T28: =T11 | U28: =U11 | V28: =V11 | W28: =(S28*12+T28*4+U28*2+V28*1) | X28: =(S28+T28+U28)/3 | Z28: investing.com
B29: 上個月剛樂觀，結果沒半個月美股全面修正，接著fed免強釋放平穩消息 | W29: =(S29*12+T29*4+U29*2+V29*1) | X29: =(S29+T29+U29)/3
B30: 彈起來又往下這樣，財報周也快結束了，感覺沒有什麼大跌，也許接近五月底會是新的機會 | R30: QQQ | S30: =QQQ!B3/QQQ!C3-1 | T30: =QQQ!B3/QQQ!C5-1 | U30: =QQQ!B3/QQQ!C8-1 | V30: =QQQ!C2/QQQ!B13-1 | W30: =(S30*12+T30*4+U30*2+V30*1) | X30: =(S30+T30+U30)/3 | Z30: 45676 | AA30: 改用python+yfinance做為資料來源
B31: 至於什麼流程自動化… 我再繼續龜縮一陣子 | AA31: 股價已yfinance,close no-adjusted為主
A32: 45446 | B32: 近日美股漲多回檔，但昨日6/2是nvidia步道大會，看起來nvda處在高檔很久，持續創高動能應該相對告
B33: 其他大型股基本轉弱，接著看動能狀況，除了vaa以外還是處在攻擊姿態，但是agg反轉
A34: 45474 | B34: 上半年結束了，幾乎就是整路qqq狂漲，上個月nv佈道大會後，繼續拉了一個月，直到6月最後一天終於出現吞噬K
B35: however,從數據上看來，連tlt都正報酬了…怎麼輸…
A36: 45505 | B36: 雖然人在高雄，也懶得用EXCEL但我想應該有譜了，乖乖用googlefinance來做weekly的資料，然後讓他自己更新了
B37: 問題在於，如果進行更新，這樣所有的資料都要重改ㄝ<好麻煩喔
B38: 先蔣捷論，看似這個月回檔結束，昨晚FOMC應該公布九月肯定降息
B39: 但是目前這樣應該都是偏弱勢，應該債券會比較強
B40: 8/5終於有空修正，想不到不斷下跌的情況下，還是以股票資產為買進目標，我想這是因為剛好花了一個月跌回月初，導致股票資產維持正數
...

Sheet VOO
A1: Date | B1: Price | C1: Open | D1: High | E1: Low | F1: Vol. | G1: Change %
A2: 46266 | B2: 700.85999 | C2: 700.85999 | D2: 700.85999 | E2: 700.85999
A3: 46235 | B3: 703.08215 | C3: 703.08215 | D3: 703.08215 | E3: 703.08215
A4: 46204 | B4: 684.88898 | C4: 684.88898 | D4: 684.88898 | E4: 684.88898
A5: 46174 | B5: 685.04852 | C5: 685.04852 | D5: 685.04852 | E5: 685.04852
A6: 46143 | B6: 691.69196 | C6: 691.69196 | D6: 691.69196 | E6: 691.69196
A7: 46113 | B7: 656.97266 | C7: 656.97266 | D7: 656.97266 | E7: 656.97266
A8: 46082 | B8: 594.28687 | C8: 594.28687 | D8: 594.28687 | E8: 594.28687
A9: 46054 | B9: 625.61914 | C9: 625.61914 | D9: 625.61914 | E9: 625.61914
A10: 46023 | B10: 630.75458 | C10: 630.75458 | D10: 630.75458 | E10: 630.75458
A11: 45992 | B11: 621.74274 | C11: 621.74274 | D11: 621.74274 | E11: 621.74274
A12: 45962 | B12: 621.25354 | C12: 621.25354 | D12: 621.25354 | E12: 621.25354
A13: 45931 | B13: 619.89911 | C13: 619.89911 | D13: 619.89911 | E13: 619.89911
A14: 45901 | B14: 605.40613 | C14: 605.40613 | D14: 605.40613 | E14: 605.40613

Sheet VXUS
A1: Date | B1: Price | C1: Open | D1: High | E1: Low | F1: Vol. | G1: Change %
A2: 46266 | B2: 84.959999 | C2: 84.959999 | D2: 84.959999 | E2: 84.959999
A3: 46235 | B3: 87.162521 | C3: 87.162521 | D3: 87.162521 | E3: 87.162521
A4: 46204 | B4: 84.437439 | C4: 84.437439 | D4: 84.437439 | E4: 84.437439
A5: 46174 | B5: 85.335823 | C5: 85.335823 | D5: 85.335823 | E5: 85.335823
A6: 46143 | B6: 85.51989 | C6: 85.51989 | D6: 85.51989 | E6: 85.51989
A7: 46113 | B7: 82.538719 | C7: 82.538719 | D7: 82.538719 | E7: 82.538719
A8: 46082 | B8: 76.62606 | C8: 76.62606 | D8: 76.62606 | E8: 76.62606
A9: 46054 | B9: 83.197655 | C9: 83.197655 | D9: 83.197655 | E9: 83.197655
A10: 46023 | B10: 79.077988 | C10: 79.077988 | D10: 79.077988 | E10: 79.077988
A11: 45992 | B11: 74.888817 | C11: 74.888817 | D11: 74.888817 | E11: 74.888817
A12: 45962 | B12: 73.050705 | C12: 73.050705 | D12: 73.050705 | E12: 73.050705
A13: 45931 | B13: 72.748512 | C13: 72.748512 | D13: 72.748512 | E13: 72.748512
A14: 45901 | B14: 71.608017 | C14: 71.608017 | D14: 71.608017 | E14: 71.608017

Sheet BND
A1: Date | B1: Price | C1: Open | D1: High | E1: Low | F1: Vol. | G1: Change %
A2: 46266 | B2: 69.901001 | C2: 69.901001 | D2: 69.901001 | E2: 69.901001
A3: 46235 | B3: 71.731483 | C3: 71.731483 | D3: 71.731483 | E3: 71.731483
A4: 46204 | B4: 71.471336 | C4: 71.471336 | D4: 71.471336 | E4: 71.471336
A5: 46174 | B5: 72.397499 | C5: 72.397499 | D5: 72.397499 | E5: 72.397499
A6: 46143 | B6: 72.203217 | C6: 72.203217 | D6: 72.203217 | E6: 72.203217
A7: 46113 | B7: 72.004677 | C7: 72.004677 | D7: 72.004677 | E7: 72.004677
A8: 46082 | B8: 71.896904 | C8: 71.896904 | D8: 71.896904 | E8: 71.896904
A9: 46054 | B9: 73.168098 | C9: 73.168098 | D9: 73.168098 | E9: 73.168098
A10: 46023 | B10: 72.014648 | C10: 72.014648 | D10: 72.014648 | E10: 72.014648
A11: 45992 | B11: 71.859421 | C11: 71.859421 | D11: 71.859421 | E11: 71.859421
A12: 45962 | B12: 72.07576 | C12: 72.07576 | D12: 72.07576 | E12: 72.07576
A13: 45931 | B13: 71.647827 | C13: 71.647827 | D13: 71.647827 | E13: 71.647827
A14: 45901 | B14: 71.218407 | C14: 71.218407 | D14: 71.218407 | E14: 71.218407

Sheet BIL
A1: Date | B1: Price | C1: Open | D1: High | E1: Low | F1: Vol. | G1: Change %
A2: 46266 | B2: 91.376999 | C2: 91.376999 | D2: 91.376999 | E2: 91.376999
A3: 46235 | B3: 91.117752 | C3: 91.117752 | D3: 91.117752 | E3: 91.117752
A4: 46204 | B4: 90.866249 | C4: 90.866249 | D4: 90.866249 | E4: 90.866249
A5: 46174 | B5: 90.560982 | C5: 90.560982 | D5: 90.560982 | E5: 90.560982
A6: 46143 | B6: 90.314911 | C6: 90.314911 | D6: 90.314911 | E6: 90.314911
A7: 46113 | B7: 90.029175 | C7: 90.029175 | D7: 90.029175 | E7: 90.029175
A8: 46082 | B8: 89.769806 | C8: 89.769806 | D8: 89.769806 | E8: 89.769806
A9: 46054 | B9: 89.512177 | C9: 89.512177 | D9: 89.512177 | E9: 89.512177
A10: 46023 | B10: 89.273788 | C10: 89.273788 | D10: 89.273788 | E10: 89.273788
A11: 45992 | B11: 89.01078 | C11: 89.01078 | D11: 89.01078 | E11: 89.01078
A12: 45962 | B12: 88.713425 | C12: 88.713425 | D12: 88.713425 | E12: 88.713425
A13: 45931 | B13: 88.459045 | C13: 88.459045 | D13: 88.459045 | E13: 88.459045
A14: 45901 | B14: 88.14959 | C14: 88.14959 | D14: 88.14959 | E14: 88.14959

Sheet VSS
A1: Date | B1: Price | C1: Open | D1: High | E1: Low | F1: Vol. | G1: Change %
A2: 46266 | B2: 155.25 | C2: 155.25 | D2: 155.25 | E2: 155.25
A3: 46235 | B3: 159.80045 | C3: 159.80045 | D3: 159.80045 | E3: 159.80045
A4: 46204 | B4: 150.23836 | C4: 150.23836 | D4: 150.23836 | E4: 150.23836
A5: 46174 | B5: 154.0013 | C5: 154.0013 | D5: 154.0013 | E5: 154.0013
A6: 46143 | B6: 159.82408 | C6: 159.82408 | D6: 159.82408 | E6: 159.82408
A7: 46113 | B7: 156.93533 | C7: 156.93533 | D7: 156.93533 | E7: 156.93533
A8: 46082 | B8: 144.72517 | C8: 144.72517 | D8: 144.72517 | E8: 144.72517
A9: 46054 | B9: 158.88103 | C9: 158.88103 | D9: 158.88103 | E9: 158.88103
A10: 46023 | B10: 151.38615 | C10: 151.38615 | D10: 151.38615 | E10: 151.38615
A11: 45992 | B11: 142.28314 | C11: 142.28314 | D11: 142.28314 | E11: 142.28314
A12: 45962 | B12: 139.38673 | C12: 139.38673 | D12: 139.38673 | E12: 139.38673
A13: 45931 | B13: 138.02933 | C13: 138.02933 | D13: 138.02933 | E13: 138.02933
A14: 45901 | B14: 138.21356 | C14: 138.21356 | D14: 138.21356 | E14: 138.21356

Sheet TLT
A1: Date | B1: Price | C1: Open | D1: High | E1: Low | F1: Vol. | G1: Change %
A2: 46266 | B2: 77.467995 | C2: 77.467995 | D2: 77.467995 | E2: 77.467995
A3: 46235 | B3: 81.875244 | C3: 81.875244 | D3: 81.875244 | E3: 81.875244
A4: 46204 | B4: 81.27993 | C4: 81.27993 | D4: 81.27993 | E4: 81.27993
A5: 46174 | B5: 85.086502 | C5: 85.086502 | D5: 85.086502 | E5: 85.086502
A6: 46143 | B6: 84.105865 | C6: 84.105865 | D6: 84.105865 | E6: 84.105865
A7: 46113 | B7: 83.659645 | C7: 83.659645 | D7: 83.659645 | E7: 83.659645
A8: 46082 | B8: 84.368057 | C8: 84.368057 | D8: 84.368057 | E8: 84.368057
A9: 46054 | B9: 88.094498 | C9: 88.094498 | D9: 88.094498 | E9: 88.094498
A10: 46023 | B10: 84.193199 | C10: 84.193199 | D10: 84.193199 | E10: 84.193199
A11: 45992 | B11: 84.222176 | C11: 84.222176 | D11: 84.222176 | E11: 84.222176
A12: 45962 | B12: 86.522476 | C12: 86.522476 | D12: 86.522476 | E12: 86.522476
A13: 45931 | B13: 86.287491 | C13: 86.287491 | D13: 86.287491 | E13: 86.287491
A14: 45901 | B14: 85.112015 | C14: 85.112015 | D14: 85.112015 | E14: 85.112015

Sheet VWO
A1: Date | B1: Price | C1: Open | D1: High | E1: Low | F1: Vol. | G1: Change %
A2: 46266 | B2: 59.310001 | C2: 59.310001 | D2: 59.310001 | E2: 59.310001
A3: 46235 | B3: 60.404839 | C3: 60.404839 | D3: 60.404839 | E3: 60.404839
A4: 46204 | B4: 58.638206 | C4: 58.638206 | D4: 58.638206 | E4: 58.638206
A5: 46174 | B5: 59.576416 | C5: 59.576416 | D5: 59.576416 | E5: 59.576416
A6: 46143 | B6: 59.69511 | C6: 59.69511 | D6: 59.69511 | E6: 59.69511
A7: 46113 | B7: 58.748043 | C7: 58.748043 | D7: 58.748043 | E7: 58.748043
A8: 46082 | B8: 53.883106 | C8: 53.883106 | D8: 53.883106 | E8: 53.883106
A9: 46054 | B9: 57.920601 | C9: 57.920601 | D9: 57.920601 | E9: 57.920601
A10: 46023 | B10: 56.295639 | C10: 56.295639 | D10: 56.295639 | E10: 56.295639
A11: 45992 | B11: 53.594006 | C11: 53.594006 | D11: 53.594006 | E11: 53.594006
A12: 45962 | B12: 53.088684 | C12: 53.088684 | D12: 53.088684 | E12: 53.088684
A13: 45931 | B13: 53.743744 | C13: 53.743744 | D13: 53.743744 | E13: 53.743744
A14: 45901 | B14: 52.971367 | C14: 52.971367 | D14: 52.971367 | E14: 52.971367

Sheet LQD
A1: Date | B1: Price | C1: Open | D1: High | E1: Low | F1: Vol. | G1: Change %
A2: 46266 | B2: 101.741 | C2: 101.741 | D2: 101.741 | E2: 101.741
A3: 46235 | B3: 105.31159 | C3: 105.31159 | D3: 105.31159 | E3: 105.31159
A4: 46204 | B4: 104.89713 | C4: 104.89713 | D4: 104.89713 | E4: 104.89713
A5: 46174 | B5: 107.30408 | C5: 107.30408 | D5: 107.30408 | E5: 107.30408
A6: 46143 | B6: 107.18308 | C6: 107.18308 | D6: 107.18308 | E6: 107.18308
A7: 46113 | B7: 106.26669 | C7: 106.26669 | D7: 106.26669 | E7: 106.26669
A8: 46082 | B8: 105.96796 | C8: 105.96796 | D8: 105.96796 | E8: 105.96796
A9: 46054 | B9: 108.21099 | C9: 108.21099 | D9: 108.21099 | E9: 108.21099
A10: 46023 | B10: 106.74015 | C10: 106.74015 | D10: 106.74015 | E10: 106.74015
A11: 45992 | B11: 106.3733 | C11: 106.3733 | D11: 106.3733 | E11: 106.3733
A12: 45962 | B12: 107.16361 | C12: 107.16361 | D12: 107.16361 | E12: 107.16361
A13: 45931 | B13: 106.17493 | C13: 106.17493 | D13: 106.17493 | E13: 106.17493
A14: 45901 | B14: 106.01647 | C14: 106.01647 | D14: 106.01647 | E14: 106.01647

Sheet IEF
A1: Date | B1: Price | C1: Open | D1: High | E1: Low | F1: Vol. | G1: Change %
A2: 46266 | B2: 89.002998 | C2: 89.002998 | D2: 89.002998 | E2: 89.002998
A3: 46235 | B3: 92.090355 | C3: 92.090355 | D3: 92.090355 | E3: 92.090355
A4: 46204 | B4: 91.983101 | C4: 91.983101 | D4: 91.983101 | E4: 91.983101
A5: 46174 | B5: 93.278496 | C5: 93.278496 | D5: 93.278496 | E5: 93.278496
A6: 46143 | B6: 93.044731 | C6: 93.044731 | D6: 93.044731 | E6: 93.044731
A7: 46113 | B7: 93.062431 | C7: 93.062431 | D7: 93.062431 | E7: 93.062431
A8: 46082 | B8: 93.202538 | C8: 93.202538 | D8: 93.202538 | E8: 93.202538
A9: 46054 | B9: 95.416374 | C9: 95.416374 | D9: 95.416374 | E9: 95.416374
A10: 46023 | B10: 93.116425 | C10: 93.116425 | D10: 93.116425 | E10: 93.116425
A11: 45992 | B11: 93.329948 | C11: 93.329948 | D11: 93.329948 | E11: 93.329948
A12: 45962 | B12: 94.045815 | C12: 94.045815 | D12: 94.045815 | E12: 94.045815
A13: 45931 | B13: 93.12561 | C13: 93.12561 | D13: 93.12561 | E13: 93.12561
A14: 45901 | B14: 92.467918 | C14: 92.467918 | D14: 92.467918 | E14: 92.467918

Sheet SHY
A1: Date | B1: Price | C1: Open | D1: High | E1: Low | F1: Vol. | G1: Change %
A2: 46266 | B2: 80.959 | C2: 80.959 | D2: 80.959 | E2: 80.959
A3: 46235 | B3: 81.403679 | C3: 81.403679 | D3: 81.403679 | E3: 81.403679
A4: 46204 | B4: 81.263512 | C4: 81.263512 | D4: 81.263512 | E4: 81.263512
A5: 46174 | B5: 81.136665 | C5: 81.136665 | D5: 81.136665 | E5: 81.136665
A6: 46143 | B6: 81.08429 | C6: 81.08429 | D6: 81.08429 | E6: 81.08429
A7: 46113 | B7: 81.022217 | C7: 81.022217 | D7: 81.022217 | E7: 81.022217
A8: 46082 | B8: 80.867989 | C8: 80.867989 | D8: 80.867989 | E8: 80.867989
A9: 46054 | B9: 81.247002 | C9: 81.247002 | D9: 81.247002 | E9: 81.247002
A10: 46023 | B10: 80.817238 | C10: 80.817238 | D10: 80.817238 | E10: 80.817238
A11: 45992 | B11: 80.65168 | C11: 80.65168 | D11: 80.65168 | E11: 80.65168
A12: 45962 | B12: 80.414665 | C12: 80.414665 | D12: 80.414665 | E12: 80.414665
A13: 45931 | B13: 80.063332 | C13: 80.063332 | D13: 80.063332 | E13: 80.063332
A14: 45901 | B14: 79.797028 | C14: 79.797028 | D14: 79.797028 | E14: 79.797028

Sheet QQQ
A1: Date | B1: Price | C1: Open | D1: High | E1: Low | F1: Vol. | G1: Change %
A2: 46266 | B2: 739.77002 | C2: 739.77002 | D2: 739.77002 | E2: 739.77002
A3: 46235 | B3: 716.01392 | C3: 716.01392 | D3: 716.01392 | E3: 716.01392
A4: 46204 | B4: 687.27386 | C4: 687.27386 | D4: 687.27386 | E4: 687.27386
A5: 46174 | B5: 735.63348 | C5: 735.63348 | D5: 735.63348 | E5: 735.63348
A6: 46143 | B6: 736.73181 | C6: 736.73181 | D6: 736.73181 | E6: 736.73181
A7: 46113 | B7: 666.31268 | C7: 666.31268 | D7: 666.31268 | E7: 666.31268
A8: 46082 | B8: 575.94623 | C8: 575.94623 | D8: 575.94623 | E8: 575.94623
A9: 46054 | B9: 605.22876 | C9: 605.22876 | D9: 605.22876 | E9: 605.22876
A10: 46023 | B10: 619.75928 | C10: 619.75928 | D10: 619.75928 | E10: 619.75928
A11: 45992 | B11: 612.22491 | C11: 612.22491 | D11: 612.22491 | E11: 612.22491
A12: 45962 | B12: 616.354 | C12: 616.354 | D12: 616.354 | E12: 616.354
A13: 45931 | B13: 626.12817 | C13: 626.12817 | D13: 626.12817 | E13: 626.12817
A14: 45901 | B14: 597.56238 | C14: 597.56238 | D14: 597.56238 | E14: 597.56238
